Workbook

Sheet Summary
A1: Framework v2 coverage of the 50 XAI-relevant guidelines
A2: Final ratings agreed 13 Oct 2026, updated 14 Oct (G16, G17, G58 built). Source: XAI guideline evidence catalogue v2 (5 Oct) and Framework v2 (11 Oct), checked against ews-mobile/model/.
A4: 1. Final coverage
A5: Rating | B5: Guidelines | C5: Share
A6: Covered | B6: =COUNTIF('Final ratings'!$E$2:$E$51,A6) -> 13 | C6: =IF($B$10=0,0,B6/$B$10) -> 0.26
A7: Partly | B7: =COUNTIF('Final ratings'!$E$2:$E$51,A7) -> 20 | C7: =IF($B$10=0,0,B7/$B$10) -> 0.4
A8: UI only | B8: =COUNTIF('Final ratings'!$E$2:$E$51,A8) -> 9 | C8: =IF($B$10=0,0,B8/$B$10) -> 0.18
A9: Not covered | B9: =COUNTIF('Final ratings'!$E$2:$E$51,A9) -> 8 | C9: =IF($B$10=0,0,B9/$B$10) -> 0.16
A10: Total | B10: =SUM(B6:B9) -> 50 | C10: =SUM(C6:C9) -> 1
A12: 2. Final coverage by evidence class
A13: Rating | B13: Direct | C13: Indirect | D13: None found | E13: Total
A14: Covered | B14: =COUNTIFS('Final ratings'!$E$2:$E$51,$A14,'Final ratings'!$C$2:$C$51,B$13) -> 10 | C14: =COUNTIFS('Final ratings'!$E$2:$E$51,$A14,'Final ratings'!$C$2:$C$51,C$13) -> 2 | D14: =COUNTIFS('Final ratings'!$E$2:$E$51,$A14,'Final ratings'!$C$2:$C$51,D$13) -> 1 | E14: =SUM(B14:D14) -> 13
A15: Partly | B15: =COUNTIFS('Final ratings'!$E$2:$E$51,$A15,'Final ratings'!$C$2:$C$51,B$13) -> 17 | C15: =COUNTIFS('Final ratings'!$E$2:$E$51,$A15,'Final ratings'!$C$2:$C$51,C$13) -> 3 | D15: =COUNTIFS('Final ratings'!$E$2:$E$51,$A15,'Final ratings'!$C$2:$C$51,D$13) -> 0 | E15: =SUM(B15:D15) -> 20
A16: UI only | B16: =COUNTIFS('Final ratings'!$E$2:$E$51,$A16,'Final ratings'!$C$2:$C$51,B$13) -> 4 | C16: =COUNTIFS('Final ratings'!$E$2:$E$51,$A16,'Final ratings'!$C$2:$C$51,C$13) -> 3 | D16: =COUNTIFS('Final ratings'!$E$2:$E$51,$A16,'Final ratings'!$C$2:$C$51,D$13) -> 2 | E16: =SUM(B16:D16) -> 9
A17: Not covered | B17: =COUNTIFS('Final ratings'!$E$2:$E$51,$A17,'Final ratings'!$C$2:$C$51,B$13) -> 7 | C17: =COUNTIFS('Final ratings'!$E$2:$E$51,$A17,'Final ratings'!$C$2:$C$51,C$13) -> 1 | D17: =COUNTIFS('Final ratings'!$E$2:$E$51,$A17,'Final ratings'!$C$2:$C$51,D$13) -> 0 | E17: =SUM(B17:D17) -> 8
A18: Total | B18: =SUM(B14:B17) -> 38 | C18: =SUM(C14:C17) -> 9 | D18: =SUM(D14:D17) -> 3 | E18: =SUM(E14:E17) -> 50
A20: 3. How the ratings changed
A21: Rating | B21: First pass (Claude) | C21: Second (Minindu) | D21: Re-audit (LLM) | E21: Final
A22: Covered | B22: =COUNTIF('Rating history'!$C$2:$C$51,$A22) -> 22 | C22: =COUNTIF('Rating history'!$D$2:$D$51,$A22) -> 3 | D22: =COUNTIF('Rating history'!$E$2:$E$51,$A22) -> 6 | E22: =COUNTIF('Rating history'!$F$2:$F$51,$A22) -> 13
A23: Partly | B23: =COUNTIF('Rating history'!$C$2:$C$51,$A23) -> 14 | C23: =COUNTIF('Rating history'!$D$2:$D$51,$A23) -> 27 | D23: =COUNTIF('Rating history'!$E$2:$E$51,$A23) -> 23 | E23: =COUNTIF('Rating history'!$F$2:$F$51,$A23) -> 20
A24: UI only | B24: =COUNTIF('Rating history'!$C$2:$C$51,$A24) -> 9 | C24: =COUNTIF('Rating history'!$D$2:$D$51,$A24) -> 0 | D24: =COUNTIF('Rating history'!$E$2:$E$51,$A24) -> 0 | E24: =COUNTIF('Rating history'!$F$2:$F$51,$A24) -> 9
A25: Not covered | B25: =COUNTIF('Rating history'!$C$2:$C$51,$A25) -> 5 | C25: =COUNTIF('Rating history'!$D$2:$D$51,$A25) -> 20 | D25: =COUNTIF('Rating history'!$E$2:$E$51,$A25) -> 21 | E25: =COUNTIF('Rating history'!$F$2:$F$51,$A25) -> 8
A26: Total | B26: =SUM(B22:B25) -> 50 | C26: =SUM(C22:C25) -> 50 | D26: =SUM(D22:D25) -> 50 | E26: =SUM(E22:E25) -> 50
A27: Rows where final differs from re-audit | B27: =COUNTIF('Rating history'!$G$2:$G$51,"Yes") -> 18
A29: 4. Sentence for the paper
A30: ="Of the "&B10&" explanation-relevant guidelines, "&B6&" are handled by a framework element (profile field, invariant, capability or layer), "&B7&" partly, "&B8&" by the interface alone, and "&B9&" are not yet covered." -> Of the 50 explanation-relevant guidelines, 13 are handled by a framework element (profile field, invariant, capability or layer), 20 partly, 9 by the interface alone, and 8 are not yet covered.
A32: Coverage shows where a guideline is handled; it is not evidence that the framework helps people with cognitive impairments.
A33: All counts are formulas on the Final ratings sheet: change a rating there and every table updates.

Sheet Final ratings
A1: ID | B1: Guideline | C1: Evidence class | D1: Catalogue page | E1: Final rating | F1: Framework part | G1: Where in the model | H1: Basis for the rating
A2: G4 | B2: One step per screen | C2: Direct | D2: 7 | E2: Partly | F2: L2 rule: "Why?" opens one part per screen; profile firstView | G2: ExplanationProfile.firstView; stepper in screen spec | H2: L2 controls content order/depth, but no one-step-per-screen stepper or Back/Next flow is specified.
A3: G11 | B3: Most important stands out | C3: Direct | D3: 7 | E3: Partly | F3: Invariants (hazard, action); L2 rule: bottom line first | G3: AdaptedExplanation.hazard, .action | H3: Hazard/action are retained, but the priority ordering and dominant action button are not specified.
A4: G14 | B4: Use clear words | C4: Direct | D4: 2 | E4: Partly | F4: Capability "Why": plain-word lookup for each observation | G4: ObservationId + word table | H4: supportingObservations is available; a plain-language multilingual input-to-words mapping is not specified.
A5: G16 | B5: Avoid double negatives | C5: Direct | D5: 2 | E5: Covered | F5: L2 template rule; L4 check rejects banned phrases | G5: Not yet in checkInvariants() | H5: Done 14 Oct: checkInvariants() rejects double negatives (BANNED_PHRASES, G16 group) in Layer 4 wording; tested (case "AI double negative").
A6: G18 | B6: Keep text succinct | C6: Direct | D6: 3 | E6: Partly | F6: Word budget per text slot | G6: Screen spec | H6: L3 forces a short alert line, but no word budget is set for all explanation steps.
A7: G19 | B7: Clear formatting and punctuation | C7: Direct | D7: 3 | E7: UI only | F7: Style rules for the forecast card | G7: Screen spec | H7: A screen rule, not a framework rule; not built yet because screens wait for wireframes. Not the same as missing from the framework.
A8: G21 | B8: Summary of long documents | C8: Direct | D8: 3 | E8: Partly | F8: L2 rule: one bottom-line sentence first | G8: firstView = 'mainMessage' | H8: L2 varies order/depth and L3 is concise; bottom-line-first in normal screens is unproven.
A9: G22 | B9: Separate each instruction | C9: Direct | D9: 4 | E9: Covered | F9: Action invariant as steps; profile actionDetail | G9: Action.steps, actionDetail | H9: profile.ts actionDetail = stepByStep ("numbered list, one step per line") with Action.steps[]; the checkbox is a screen detail.
A10: G25 | B10: Explain implied content | C10: Direct | D10: 4 | E10: Partly | F10: Extras: consequence line per state | G10: Extras.consequence; no capability row yet | H10: explanation.ts already has an Extras.consequence slot; what is missing is the consequence text per state.
A11: G26 | B11: Alternatives for numbers | C11: Direct | D11: 4 | E11: Covered | F11: Profile likelihoodForm; likelihood invariant | G11: likelihoodForm, Likelihood | H11: F5 demonstrates likelihoodForm=wordPictureNumber: CAP word, ten-house icon array and 29% on tap; likelihood invariant checks meaning.
A12: G41 | B12: Avoid too much content | C12: Direct | D12: 8 | E12: Covered | F12: Profile firstView (progressive disclosure) | G12: firstView | H12: The L2 profile chooses content and depth while invariants protect facts; this handles framework-side disclosure, not yet verified screen taps.
A13: G47 | B13: Don't rely on calculation | C13: Direct | D13: 5 | E13: Covered | F13: Profile timeWording; capability compare forecasts | G13: timeWording, compareForecasts() | H13: profile.ts has timeWording = dayAndPart ("Thursday morning") and compareForecasts() does the comparison; the re-audit did not have the code.
... A51: G65 | B51: Focus not obscured | C51: None found | D51: 17 | E51: UI only | F51: Layout test | G51: Screen spec | H51: A screen rule, not a framework rule; not built yet because screens wait for wireframes. Not the same as missing from the framework.

Sheet Rating history
A1: ID | B1: Guideline | C1: 1. First pass (Claude, 12 Oct) | D1: 2. Second rating (Minindu) | E1: 3. Re-audit (LLM judge) | F1: 4. Final (13 Oct) | G1: Final differs from re-audit? | H1: Why the final differs
A2: G4 | B2: One step per screen | C2: Partly | D2: Partly | E2: Partly | F2: =INDEX('Final ratings'!$E$2:$E$51,MATCH(A2,'Final ratings'!$A$2:$A$51,0)) -> Partly | G2: =IF(F2<>E2,"Yes","")
A3: G11 | B3: Most important stands out | C3: Covered | D3: Partly | E3: Partly | F3: =INDEX('Final ratings'!$E$2:$E$51,MATCH(A3,'Final ratings'!$A$2:$A$51,0)) -> Partly | G3: =IF(F3<>E3,"Yes","")
A4: G14 | B4: Use clear words | C4: Covered | D4: Partly | E4: Partly | F4: =INDEX('Final ratings'!$E$2:$E$51,MATCH(A4,'Final ratings'!$A$2:$A$51,0)) -> Partly | G4: =IF(F4<>E4,"Yes","")
A5: G16 | B5: Avoid double negatives | C5: Partly | D5: Not covered | E5: Not covered | F5: =INDEX('Final ratings'!$E$2:$E$51,MATCH(A5,'Final ratings'!$A$2:$A$51,0)) -> Covered | G5: =IF(F5<>E5,"Yes","") -> Yes | H5: Changed after the re-audit, 14 Oct: checkInvariants() rejects double negatives (BANNED_PHRASES, G16 group) in Layer 4 wording; tested (case "AI double negative").
A6: G18 | B6: Keep text succinct | C6: UI only | D6: Partly | E6: Partly | F6: =INDEX('Final ratings'!$E$2:$E$51,MATCH(A6,'Final ratings'!$A$2:$A$51,0)) -> Partly | G6: =IF(F6<>E6,"Yes","")
A7: G19 | B7: Clear formatting and punctuation | C7: UI only | D7: Not covered | E7: Not covered | F7: =INDEX('Final ratings'!$E$2:$E$51,MATCH(A7,'Final ratings'!$A$2:$A$51,0)) -> UI only | G7: =IF(F7<>E7,"Yes","") -> Yes | H7: A screen rule, not a framework rule; not built yet because screens wait for wireframes. Not the same as missing from the framework.
A8: G21 | B8: Summary of long documents | C8: Covered | D8: Partly | E8: Partly | F8: =INDEX('Final ratings'!$E$2:$E$51,MATCH(A8,'Final ratings'!$A$2:$A$51,0)) -> Partly | G8: =IF(F8<>E8,"Yes","")
A9: G22 | B9: Separate each instruction | C9: Covered | D9: Partly | E9: Partly | F9: =INDEX('Final ratings'!$E$2:$E$51,MATCH(A9,'Final ratings'!$A$2:$A$51,0)) -> Covered | G9: =IF(F9<>E9,"Yes","") -> Yes | H9: profile.ts actionDetail = stepByStep ("numbered list, one step per line") with Action.steps[]; the checkbox is a screen detail.
A10: G25 | B10: Explain implied content | C10: Partly | D10: Partly | E10: Not covered | F10: =INDEX('Final ratings'!$E$2:$E$51,MATCH(A10,'Final ratings'!$A$2:$A$51,0)) -> Partly | G10: =IF(F10<>E10,"Yes","") -> Yes | H10: explanation.ts already has an Extras.consequence slot; what is missing is the consequence text per state.
A11: G26 | B11: Alternatives for numbers | C11: Covered | D11: Covered | E11: Covered | F11: =INDEX('Final ratings'!$E$2:$E$51,MATCH(A11,'Final ratings'!$A$2:$A$51,0)) -> Covered | G11: =IF(F11<>E11,"Yes","")
A12: G41 | B12: Avoid too much content | C12: Covered | D12: Covered | E12: Covered | F12: =INDEX('Final ratings'!$E$2:$E$51,MATCH(A12,'Final ratings'!$A$2:$A$51,0)) -> Covered | G12: =IF(F12<>E12,"Yes","")
A13: G47 | B13: Don't rely on calculation | C13: Covered | D13: Partly | E13: Partly | F13: =INDEX('Final ratings'!$E$2:$E$51,MATCH(A13,'Final ratings'!$A$2:$A$51,0)) -> Covered | G13: =IF(F13<>E13,"Yes","") -> Yes | H13: profile.ts has timeWording = dayAndPart ("Thursday morning") and compareForecasts() does the comparison; the re-audit did not have the code.
A14: G48 | B14: Provide human help | C14: Not covered | D14: Not covered | E14: Not covered | F14: =INDEX('Final ratings'!$E$2:$E$51,MATCH(A14,'Final ratings'!$A$2:$A$51,0)) -> Not covered | G14: =IF(F14<>E14,"Yes","")
A15: G50 | B15: State results of actions | C15: Partly | D15: Partly | E15: Partly | F15: =INDEX('Final ratings'!$E$2:$E$51,MATCH(A15,'Final ratings'!$A$2:$A$51,0)) -> Partly | G15: =IF(F15<>E15,"Yes","")
A16: G54 | B16: Provide reminders | C16: Covered | D16: Partly | E16: Partly | F16: =INDEX('Final ratings'!$E$2:$E$51,MATCH(A16,'Final ratings'!$A$2:$A$51,0)) -> Partly | G16: =IF(F16<>E16,"Yes","")
A17: G57 | B17: Support simplification | C17: Covered | D17: Partly | E17: Partly | F17: =INDEX('Final ratings'!$E$2:$E$51,MATCH(A17,'Final ratings'!$A$2:$A$51,0)) -> Partly | G17: =IF(F17<>E17,"Yes","")
A18: G58 | B18: Personalised, persistent | C18: Covered | D18: Partly | E18: Partly | F18: =INDEX('Final ratings'!$E$2:$E$51,MATCH(A18,'Final ratings'!$A$2:$A$51,0)) -> Covered | G18: =IF(F18<>E18,"Yes","") -> Yes | H18: Changed after the re-audit, 14 Oct: ExplanationProfileContext saves the profile on the device, loads it at start-up, and lets it be edited (updateField, choosePreset).
A19: G59 | B19: Info and relationships (screen readers) | C19: UI only | D19: Not covered | E19: Not covered | F19: =INDEX('Final ratings'!$E$2:$E$51,MATCH(A19,'Final ratings'!$A$2:$A$51,0)) -> UI only | G19: =IF(F19<>E19,"Yes","") -> Yes | H19: A screen rule, not a framework rule; not built yet because screens wait for wireframes. Not the same as missing from the framework.
A20: G67 | B20: Reading level | C20: Partly | D20: Not covered | E20: Not covered | F20: =INDEX('Final ratings'!$E$2:$E$51,MATCH(A20,'Final ratings'!$A$2:$A$51,0)) -> Not covered | G20: =IF(F20<>E20,"Yes","")
A21: G73 | B21: Persistent visual context | C21: Covered | D21: Partly | E21: Covered | F21: =INDEX('Final ratings'!$E$2:$E$51,MATCH(A21,'Final ratings'!$A$2:$A$51,0)) -> Covered | G21: =IF(F21<>E21,"Yes","")
A22: G76 | B22: Realistic imagery | C22: Partly | D22: Partly | E22: Partly | F22: =INDEX('Final ratings'!$E$2:$E$51,MATCH(A22,'Final ratings'!$A$2:$A$51,0)) -> Partly | G22: =IF(F22<>E22,"Yes","")
A23: G77 | B23: Avoid metaphorical icons | C23: UI only | D23: Partly | E23: Partly | F23: =INDEX('Final ratings'!$E$2:$E$51,MATCH(A23,'Final ratings'!$A$2:$A$51,0)) -> Partly | G23: =IF(F23<>E23,"Yes","")
A24: G79 | B24: Co-design with dementia users | C24: Not covered | D24: Not covered | E24: Not covered | F24: =INDEX('Final ratings'!$E$2:$E$51,MATCH(A24,'Final ratings'!$A$2:$A$51,0)) -> Not covered | G24: =IF(F24<>E24,"Yes","")
A25: G80 | B25: Caregiver companion view | C25: Partly | D25: Partly | E25: Partly | F25: =INDEX('Final ratings'!$E$2:$E$51,MATCH(A25,'Final ratings'!$A$2:$A$51,0)) -> Partly | G25: =IF(F25<>E25,"Yes","")
A26: G81 | B26: Familiar, real-world metaphors | C26: Covered | D26: Partly | E26: Covered | F26: =INDEX('Final ratings'!$E$2:$E$51,MATCH(A26,'Final ratings'!$A$2:$A$51,0)) -> Covered | G26: =IF(F26<>E26,"Yes","")
A27: G88 | B27: Literal language + visual support | C27: Partly | D27: Partly | E27: Partly | F27: =INDEX('Final ratings'!$E$2:$E$51,MATCH(A27,'Final ratings'!$A$2:$A$51,0)) -> Partly | G27: =IF(F27<>E27,"Yes","")
A28: G89 | B28: Warning before change | C28: Covered | D28: Partly | E28: Partly | F28: =INDEX('Final ratings'!$E$2:$E$51,MATCH(A28,'Final ratings'!$A$2:$A$51,0)) -> Partly | G28: =IF(F28<>E28,"Yes","")
A29: G107 | B29: Caregiver-mediated configuration | C29: Covered | D29: Partly | E29: Partly | F29: =INDEX('Final ratings'!$E$2:$E$51,MATCH(A29,'Final ratings'!$A$2:$A$51,0)) -> Partly | G29: =IF(F29<>E29,"Yes","")
A30: G111 | B30: Calm colours in non-urgent states | C30: UI only | D30: Not covered | E30: Not covered | F30: =INDEX('Final ratings'!$E$2:$E$51,MATCH(A30,'Final ratings'!$A$2:$A$51,0)) -> UI only | G30: =IF(F30<>E30,"Yes","") -> Yes | H30: A screen rule, not a framework rule; not built yet because screens wait for wireframes. Not the same as missing from the framework.
A31: G114 | B31: Time-boxed tasks / countdown | C31: Covered | D31: Partly | E31: Partly | F31: =INDEX('Final ratings'!$E$2:$E$51,MATCH(A31,'Final ratings'!$A$2:$A$51,0)) -> Partly | G31: =IF(F31<>E31,"Yes","")
A32: G117 | B32: Definition tooltips | C32: Not covered | D32: Not covered | E32: Not covered | F32: =INDEX('Final ratings'!$E$2:$E$51,MATCH(A32,'Final ratings'!$A$2:$A$51,0)) -> Not covered | G32: =IF(F32<>E32,"Yes","")
A33: G118 | B33: Multi-modal alert | C33: Partly | D33: Not covered | E33: Not covered | F33: =INDEX('Final ratings'!$E$2:$E$51,MATCH(A33,'Final ratings'!$A$2:$A$51,0)) -> Not covered | G33: =IF(F33<>E33,"Yes","")
A34: G119 | B34: CAP message structure | C34: Covered | D34: Partly | E34: Partly | F34: =INDEX('Final ratings'!$E$2:$E$51,MATCH(A34,'Final ratings'!$A$2:$A$51,0)) -> Covered | G34: =IF(F34<>E34,"Yes","") -> Yes | H34: forecast.ts carries CAP certainty (likelihood.capCertainty), severity and urgency (Forecast.cap), and the instruction as Forecast.action.
A35: G120 | B35: Universal hazard symbols | C35: Covered | D35: Not covered | E35: Not covered | F35: =INDEX('Final ratings'!$E$2:$E$51,MATCH(A35,'Final ratings'!$A$2:$A$51,0)) -> UI only | G35: =IF(F35<>E35,"Yes","") -> Yes | H35: A screen rule, not a framework rule; not built yet because screens wait for wireframes. Not the same as missing from the framework.
A36: G121 | B36: Local-language Easy Read | C36: Partly | D36: Not covered | E36: Not covered | F36: =INDEX('Final ratings'!$E$2:$E$51,MATCH(A36,'Final ratings'!$A$2:$A$51,0)) -> Not covered | G36: =IF(F36<>E36,"Yes","")
A37: G124 | B37: One decision under stress | C37: Partly | D37: Partly | E37: Partly | F37: =INDEX('Final ratings'!$E$2:$E$51,MATCH(A37,'Final ratings'!$A$2:$A$51,0)) -> Partly | G37: =IF(F37<>E37,"Yes","")
A38: G125 | B38: Pre-rehearsed action plan | C38: Not covered | D38: Not covered | E38: Not covered | F38: =INDEX('Final ratings'!$E$2:$E$51,MATCH(A38,'Final ratings'!$A$2:$A$51,0)) -> Not covered | G38: =IF(F38<>E38,"Yes","")
A39: G128 | B39: Multiple representations | C39: Covered | D39: Partly | E39: Partly | F39: =INDEX('Final ratings'!$E$2:$E$51,MATCH(A39,'Final ratings'!$A$2:$A$51,0)) -> Covered | G39: =IF(F39<>E39,"Yes","") -> Yes | H39: profile.ts has modality = text | audio | pictures; producing the audio is screen work.
A40: G15 | B40: Simple tense and voice | C40: UI only | D40: Not covered | E40: Not covered | F40: =INDEX('Final ratings'!$E$2:$E$51,MATCH(A40,'Final ratings'!$A$2:$A$51,0)) -> UI only | G40: =IF(F40<>E40,"Yes","") -> Yes | H40: A screen rule, not a framework rule; not built yet because screens wait for wireframes. Not the same as missing from the framework.
...

Sheet Gaps and actions
A1: Guideline(s) | B1: Gap | C1: Suggested action | D1: Decision | E1: Owner | F1: Due
A2: G16, G17 | B2: checkInvariants() does not reject double negatives ("not unlikely") or idioms in L4 wording | C2: Add a banned-phrase and idiom list to checkInvariants() | D2: Done | E2: Minindu | F2: 46308
A3: G25 | B3: No consequence line per forecast state ("Water may come into houses near the river") | C3: Add consequence text per severity class; slot already exists (Extras.consequence) | D3: Fix now | E3: Minindu | F3: 46311
A4: G121 | B4: Language: catalogue says it comes from the profile; 9 Oct decision said app setting | C4: Keep the app setting and change the catalogue line (recommended) | D4: Decide | E4: Minindu | F4: 46309
A5: G124 | B5: Alert mode: G124 says hazard and action only; Framework v2 keeps all five facts | C5: Question 2 at the supervisor meeting | D5: Ask Madam | E5: Minindu | F5: 46310
A6: G67 | B6: No reading-level setting in the profile | C6: Ask Madam, or report that templates use one Easy Read level | D6: Ask Madam | E6: Minindu | F6: 46310
A7: G48 | B7: No saved helper contact for "Ask someone to explain" | C7: Add helperContact to the profile, or report as future work | D7: Decide | E7: Minindu | F7: 46311
A8: G118 | B8: No multi-channel change notification (text, voice, vibration) | C8: Report as limitation; prototype uses one channel | D8: Limitation
A9: G117 | B9: No tap-to-define tooltips | C9: Report: evidence favours removing jargon over tooltips | D9: Limitation
A10: G125 | B10: No calm-time practice mode | C10: Report as future work | D10: Limitation
A11: G79 | B11: Co-design with users and carers not done | C11: Report as future work (no user study) | D11: Limitation
A12: G80 | B12: No second carer profile or view | C12: Report as future work; consent record exists | D12: Limitation
A13: G76, G38 | B13: Landmark levels and photos are placeholders | C13: Report: no source gives real landmark levels | D13: Limitation
A14: UI only (9) | B14: G15, G19, G20, G23, G24, G59, G65, G111, G120 are screen rules | C14: Build into screen specs S07–S11 after wireframes (22 Oct) | D14: Screen work | E14: Minindu, Supun | F14: 46324
A16: Yellow cells (Decision) are yours to update as each gap is settled.

Sheet Method
A1: Item | B1: Definition or note
A2: Scope | B2: 50 XAI-relevant guidelines from the evidence catalogue v2 (38 Direct, 9 Indirect, 3 None found), checked against Framework v2 (11 Oct 2026) and the data model in ews-mobile/model/ (commit 7e65fa9).
A3: Covered | B3: A named framework element (profile field, invariant, capability or layer) handles the guideline's main explanation requirement, and it can be pointed to in the data model.
A4: Partly | B4: The framework handles part of it; a field, capability or rule is missing.
A5: UI only | B5: A screen rule, not a framework rule. Not built yet because screens wait for wireframes (22 Oct). Not the same as missing from the framework.
A6: Not covered | B6: Nothing in the framework or the screens handles it yet.
A7: Evidence class | B7: Direct / Indirect / None found is the strength of published evidence for the guideline (catalogue). It is separate from coverage.
A8: Process | B8: 1. Claude first pass from the catalogue (12 Oct). 2. Minindu second rating. 3. LLM re-audit (ChatGPT as judge) of the second rating, without the code. 4. Final: re-audit kept except 15 rows corrected against the code or moved to UI only (13 Oct).
A9: AI use (disclose) | B9: Steps 1 and 3 used AI tools. The first author checked every row. Report the mapping as the authors' analysis with AI assistance; do not present the LLM re-audit as an independent rater.
A10: Limits | B10: Screens S07–S11 and theme files were not yet built, so UI-only rows are unverified. Coverage is not evidence of benefit for people with cognitive impairments.
